Workbook
Name _1_2: #REF!
Name _1_2: #REF!
Name _1_2: #REF!
Name _1_2: #REF!
Name _1000V_XLPE: #REF!
Name _1000V_XLPE: #REF!
Name _1000V_XLPE: #REF!
Name _25kV_XLPE: #REF!
Name _25kV_XLPE: #REF!
Name _600_XLPE: #REF!
Name _600V_XLPE: #REF!
Name C型鋼: [1]!C型鋼規格表[[#All],[規格]]
Name EMT管: #REF!
Name PV_Cable: #REF!
Name PV_Cable: #REF!
Name PV_Cable: #REF!
Name PV_Cable: #REF!
Name PVC_Cable: #REF!
Name PVC_Cable: #REF!
Name PVC_Cable: #REF!
Name PVC管: #REF!
Name PVC管: #REF!
Name PVC管: #REF!
Name RH型鋼: [1]!RH型鋼規格表[[#All],[欄2]]
Name RSG管: #REF!
Name 不等邊方型鋼: [1]!不等邊方型鋼規格表[[#All],[規格]]
Name 不鏽鋼管: #REF!
Name 加工類: [1]!物料分類表[加工類]
Name 交通類: [1]!物料分類表[交通類]
Name 我: #REF!
Name 尚未分類: [1]!物料分類表[尚未分類]
Name 板材: [1]!板材規格表[[#All],[規格]]
Name 表面處理: [1]!表面處理規格表[[#All],[規格]]
Name 金屬材料類: [1]!物料分類表[金屬材料類]
Name 堆高機: #REF!
Name 密閉式線槽: #REF!
Name 清洗管路: #REF!
Name 球塞閥: #REF!
Name 等邊方型鋼: [1]!等邊方型鋼規格表[[#All],[規格]]
Name 等邊角鐵: [1]!等邊角鐵規格表[規格]
Name 開放式線架: #REF!
Name 電工材料類: [1]!物料分類表[電工材料類]
Name 緊固件類: [1]!物料分類表[緊固件類]
Name 鋼構鋼材類: [1]!物料分類表[鋼構鋼材類]
Name 雜配件類: [1]!物料分類表[雜配件類]
Name 變流器: #REF!
Name 變流器1: #REF!

Sheet 成本分析表
A2: 專案成本分析表
A4: 客戶名稱： | B4: =報價單!B3 -> 夸克能源股份有限公司 | E4: 案場類型：
A5: 工程區域： | B5: =報價單!B4 -> 宜蘭縣冬山鄉順安路185巷1號 | E5: 建置容量： | F5: =報價單!$D$48 -> 70.55 | G5: kWp
A6: 專案名稱： | B6: =報價單!B5 -> 宜蘭順安美麗莊園-光電工程-70.55kWp | E6: 日期： | F6: =報價單!$F$3 -> 46153
A7: 合約總價： | B7: =E10 -> 4014295 | C7: 未稅 | E7: REV： | F7: V1.0
A8: 客戶來源： | B8: 自行開發 | E8: 業務： | F8: =報價單!$F$4 -> TEST
A9: 分項 | B9: 項目 | E9: 費用 | F9: kWp | G9: % | I9: 項目 | L9: 金額 | M9: kWp | N9: %
A10: 收入--(A) (預估報價) | E10: =報價單!F48 -> 4014295 | F10: =E10/$F$5 -> 56900 | G10: 1 | I10: 報價總價 | L10: =$E$13 -> 4014295 | M10: =$F$10 -> 56900 | N10: 1 | P10: 公式加總欄位
I11: 鋼構工程材料費 | L11: =工程預算書!$F$9+工程預算書!$F$10+工程預算書!$F$11+工程預算書!$F$12+工程預算書!$F$13+工程預算書!$F$14+工程預算書!$F$15+工程預算書!$F$16+工程預算書!$F$17+工程預算書!$F$19+工程預算書!$F$20+工程預算書!$F$21+工程預算書!$F$22+工程預算書!$F$25 -> 536810.9 | M11: =L11/$F$5 -> 7608.9426 | N11: =L11/$L$10 -> 0.13372483 | P11: 9.10.11.12.13.14.15.16.17.19.20.21.22.25
I12: 鋼構組立工資 | L12: =工程預算書!$F$18 +工程預算書!$F$23+工程預算書!$F$24+工程預算書!$F$26 -> 190605.6 | M12: =L12/$F$5 -> 2701.7094 | N12: =L12/$L$10 -> 0.047481712 | P12: 18.23.24.26
B13: (A)收入總計 | E13: =SUM(E10:E12) -> 4014295 | F13: =E13/$F$5 -> 56900 | G13: =E13/E10 -> 1 | I13: 浪板工程 | L13: =工程預算書!$F$36 -> 258745 | M13: =L13/$F$5 -> 3667.5408 | N13: =L13/$L$10 -> 0.064455901
A14: 營業成本(B) | I14: 鋁支架與安全設施材料 | L14: =工程預算書!$F$39+工程預算書!$F$42+工程預算書!$F$43 -> 269600 | M14: =L14/$F$5 -> 3821.4033 | N14: =L14/$L$10 -> 0.067159987 | P14: 39.42.43
B15: 材料 | E15: =L13+L17+L18+L19+L11+L15+L16 -> 2146005.9 | F15: =E15/$F$5 -> 30418.227 | G15: =E15/$E$13 -> 0.53459098 | I15: 鋁支架與模組鋪設工資 | L15: =工程預算書!$F$40+工程預算書!$F$41 -> 156100 | M15: =L15/$F$5 -> 2212.6152 | N15: =L15/$L$10 -> 0.038886031 | P15: 40.41
B16: 工資 | E16: =L14+L20+L22+L12 -> 707130.6 | F16: =E16/$F$5 -> 10023.113 | G16: =E16/$E$13 -> 0.17615312 | I16: 土建工程 | L16: =工程預算書!$F$46 -> 0 | M16: =L16/$F$5 -> 0 | N16: =L16/$L$10 -> 0
B17: 簽證跑照費 | E17: =L21 -> 171840 | F17: =E17/$F$5 -> 2435.7193 | G17: =E17/$E$13 -> 0.042807018 | I17: 設備類 | L17: =VLOOKUP(I17,工程預算書!$B:$F,5,0) -> 141100 | M17: =L17/$F$5 -> 2000 | N17: =L17/$L$10 -> 0.035149385
B18: 開發費 | C18: 5000 | E18: =F18*F5 -> 70550 | F18: 1000 | G18: =E18/$E$13 -> 0.017574692 | I18: 機電盤體工程 | L18: =VLOOKUP(I18,工程預算書!$B:$F,5,0) -> 720775 | M18: =L18/$F$5 -> 10216.513 | N18: =L18/$L$10 -> 0.17955208
B19: =I23 -> 雜項費用2% | E19: =L23 -> 60499.53 | F19: =E19/$F$5 -> 857.54118 | G19: =E19/$E$13 -> 0.015071022 | I19: 配管線材料 | L19: =工程預算書!$F$87+工程預算書!$F$88+工程預算書!$F$89+工程預算書!$F$90+工程預算書!$F$91 -> 332475 | M19: =L19/$F$5 -> 4712.6152 | N19: =L19/$L$10 -> 0.082822762 | P19: 87-91 | Q19: =工程預算書!$F$87+工程預算書!$F$88+工程預算書!$F$89+工程預算書!$F$90+工程預算書!$F$91 -> 332475
B20: =I26 -> 工程保險0.8% | E20: =L26 -> 24199.812 | F20: =E20/$F$5 -> 343.01647 | G20: =E20/$E$13 -> 0.006028409 | I20: 機電工資 | L20: =工程預算書!$F$92+工程預算書!$F$93 -> 134045 | M20: =L20/$F$5 -> 1900 | N20: =L20/$L$10 -> 0.033391916 | P20: 92.93 | Q20: =工程預算書!$F$92+工程預算書!$F$93 -> 134045
I21: 簽證及各類文件申請跑件 | L21: =VLOOKUP(I21,工程預算書!$B:$F,5,0) -> 171840 | M21: =L21/$F$5 -> 2435.7193 | N21: =L21/$L$10 -> 0.042807018
B22: 營業成本總計 | E22: =SUM(E15:E20) -> 3180225.8 | F22: =E22/$F$5 -> 45077.616 | G22: =E22/$E$13 -> 0.79222525 | I22: 其他及假設工程 | L22: =VLOOKUP(I22,工程預算書!$B:$F,5,0) -> 112880 | M22: =L22/$F$5 -> 1600 | N22: =L22/$L$10 -> 0.028119508
A23: 營業毛利(F) | B23: (F)毛利=(A)-(B) | E23: =E13-E22 -> 834069.16 | F23: =E23/$F$5 -> 11822.384 | G23: =E23/$E$13 -> 0.20777475 | I23: 雜項費用2% | L23: =VLOOKUP(I23,工程預算書!$B:$F,5,0) -> 60499.53 | M23: =L23/$F$5 -> 857.54118 | N23: =L23/$L$10 -> 0.015071022
A24: 營業費用(G) | B24: =I24 -> 工程設計技術整合費1% | E24: =L24 -> 30249.765 | F24: =E24/$F$5 -> 428.77059 | G24: =E24/$E$13 -> 0.0075355112 | I24: 工程設計技術整合費1% | L24: =VLOOKUP(I24,工程預算書!$B:$F,5,0) -> 30249.765 | M24: =L24/$F$5 -> 428.77059 | N24: =L24/$L$10 -> 0.0075355112
B25: =I27 -> 工程保固1% | E25: =L27 -> 30249.765 | F25: =E25/$F$5 -> 428.77059 | G25: =E25/$E$13 -> 0.0075355112 | I25: 小計 | L25: =SUM(L11:L24) -> 3115725.8 | M25: =SUM(M13:M24) -> 33852.719 | N25: =SUM(N11:N24) -> 0.77615766
B26: =I28 -> 內部管銷5% | E26: =L28 -> 151248.83 | F26: =E26/$F$5 -> 2143.8529 | G26: =E26/$E$13 -> 0.037677556 | I26: 工程保險0.8% | L26: =VLOOKUP(I26,工程預算書!$B:$F,5,0) -> 24199.812 | M26: =L26/$F$5 -> 343.01647 | N26: =L26/$L$10 -> 0.006028409
B27: 風險評估費2% | E27: =$E$13*G27 -> 80285.9 | F27: =E27/$F$5 -> 1138 | G27: 0.02 | I27: 工程保固1% | L27: =VLOOKUP(I27,工程預算書!$B:$F,5,0) -> 30249.765 | M27: =L27/$F$5 -> 428.77059 | N27: =L27/$L$10 -> 0.0075355112
I28: 內部管銷5% | L28: =VLOOKUP(I28,工程預算書!$B:$F,5,0) -> 151248.83 | M28: =L28/$F$5 -> 2143.8529 | N28: =L28/$L$10 -> 0.037677556
I29: 風險評估費 | L29: =E27 -> 80285.9 | M29: =L29/$F$5 -> 1138 | N29: =L29/$L$10 -> 0.02
B30: 營業費用總計 | E30: =SUM(E24:E28) -> 292034.26 | F30: =E30/$F$5 -> 4139.3941 | G30: =E30/E13 -> 0.072748579 | I30: 小計 | L30: =SUM(L26:L29) -> 285984.3 | M30: =SUM(M26:M29) -> 4053.64 | N30: =SUM(N26:N29) -> 0.071241476
A31: 營業淨利 | B31: (H)營業淨利=(F)-(G) | E31: =E13-E22-E30 -> 542034.9 | F31: =E31/$F$5 -> 7682.9894 | G31: =E31/$E$13 -> 0.13502618 | I31: 耐斯傑開發費 | L31: =E18 -> 70550 | M31: =L31/$F$5 -> 1000 | N31: =L31/$L$10 -> 0.017574692
A32: 營所稅(I) | B32: =(A)*2% | E32: =E13*2% -> 80285.9 | G32: =E32/$E$13 -> 0.02 | I32: 營所稅 | L32: =E32 -> 80285.9 | M32: =L32/$F$5 -> 1138 | N32: =L32/$L$10 -> 0.02
A33: 稅後淨利率 | B33: (J)稅後淨利=(H)-(I) | E33: =E31-E32 -> 461749 | G33: =E33/$E$13 -> 0.11502618 | I33: 稅後淨利 | L33: =E33 -> 461749 | M33: =L33/$F$5 -> 6544.9894 | N33: =L33/$L$10 -> 0.11502618
A34: 註1：依實際收入及成本項目填入 | I34: 小計 | L34: =SUM(L31:L33) -> 612584.9 | M34: =SUM(M31:M33) -> 8682.9894 | N34: =SUM(N31:N33) -> 0.15260087
A35: 註2：各專案工、費金額以前一年度工費%為估列基礎 | I35: 總計 | L35: =L34+L30+L25 -> 4014295 | M35: =M34+M30+M25 -> 46589.348 | N35: =N25+N34+N30 -> 1
A36: 註3：營業費用%以前一年度營業費用%為估列基礎
A37: 註4：此表請於3日內簽核完畢
A39: 製表： | D39: 覆核：
A42: 業務主管： | D42: 財務單位： | F42: 總經理：
A45: 分攤費用基礎:
A46: 1.共同費用：保險費(含人員及車輛)、車輛折舊及保養維修及加油、租金(含廠房、車輛及影印機等)、退休金
A47: 2.專案費用：旅費、運費、技師勞務費等

Sheet 報價單
A2: 工 程 報 價 單 | I2: ↓填入kWp
A3: 客戶名稱 | B3: 夸克能源股份有限公司 | E3: 報價日期 | F3: 46153 | I3: 70.55
A4: 設置地點 | B4: 宜蘭縣冬山鄉順安路185巷1號 | E4: 負責業務 | F4: TEST | I4: 預算 | K4: 報價
A5: 工程名稱 | B5: 宜蘭順安美麗莊園-光電工程-70.55kWp | E5: e-mail | F5: sales.nextgenenergy@gmail.com | K5: 1.23
A6: 項目 | B6: 工程項目 | C6: 單位 | D6: 數量 | E6: 單價 | F6: 複價 | G6: 備註
A7: 壹 | B7: 鋼構工程 | I7: =工程預算書!G28 -> 10310.652 | K7: =I7*$K$5 -> 12682.102
A8: 1 | B8: H型鋼 | C8: kWp | D8: =$I$3 -> 70.55 | E8: 11000 | F8: =ROUND(E8*D8,0) -> 776050 | G8: 黑鐵+熱浸鍍鋅 | K8: =I8*$K$6 -> 0
A9: 2 | B9: C型鋼 | G9: 黑鐵+熱浸鍍鋅 含二工材料 | K9: =I9*$K$6 -> 0
A10: 3 | B10: 鋼構螺絲 | G10: 熱浸鍍鋅/A325 | K10: =I10*$K$6 -> 0
A11: 4 | B11: 鋼構運輸 | K11: =I11*$K$6 -> 0
A12: 5 | B12: 基礎座 | G12: 含無收縮水泥、基礎螺絲、植筋膠 | K12: =I12*$K$6 -> 0
A13: 6 | B13: 不鏽鋼爬梯
A14: 7 | B14: 鋼構組立工資 | G14: 含機具 | K14: =I14*$K$6 -> 0
A15: 貳 | B15: 浪板工程 | I15: =工程預算書!G36 -> 3667.5408 | K15: =I15*$K$5 -> 4511.0751
A16: 1 | B16: 浪板 | C16: =C8 -> kWp | D16: =$I$3 -> 70.55 | E16: 5000 | F16: =ROUND(E16*D16,0) -> 352750 | G16: K27 0.5t清板 含二工材料 | K16: =I16*$K$5 -> 0
A17: 2 | B17: 中脊與包邊 | K17: =I17*$K$5 -> 0
A18: 3 | B18: 白鐵水槽+PVC排水管 | K18: =I18*$K$5 -> 0
A19: 4 | B19: 浪板吊運費
A20: 參 | B20: 鋁擠支架及模組鋪設工程 | I20: =工程預算書!G45 -> 6034.0184 | K20: =I20*$K$5 -> 7421.8427
A21: 1 | B21: 鋁支架材料費 | C21: =C16 -> kWp | D21: =$I$3 -> 70.55 | E21: 8300 | F21: =ROUND(E21*D21,0) -> 585565 | G21: 含中壓、側壓、五金零件 | K21: =I21*$K$5 -> 0
A22: 2 | B22: 安全設施 | G22: 維修步道、圍籬 | K22: =I22*$K$5 -> 0
A23: 3 | B23: 鋁支架運輸費 | K23: =I23*$K$5 -> 0
A24: 4 | B24: 鋁支架安裝+模組鋪設 | G24: 含機具、吊掛 | K24: =I24*$K$5 -> 0
A25: 肆 | B25: 土建工程 | I25: =工程預算書!G51 -> 0 | K25: =I25*$K$5 -> 0
A26: 1 | B26: 場鑄獨立基礎(含工) | C26: kWp | D26: =$I$3 -> 70.55 | E26: 0 | F26: =ROUND(E26*D26,0) -> 0
A27: 2 | B27: 切割及開挖處復原
A28: 伍 | B28: 設備類 | I28: =工程預算書!G58 -> 2000 | K28: =I28*$K$5 -> 2460
A29: 1 | B29: 單晶矽太陽能模組 | C29: kWp | D29: =$I$3 -> 70.55 | E29: 3000 | F29: =ROUND(E29*D29,0) -> 211650 | G29: VSUN590N-144BMH-DG
A30: 2 | B30: 逆變器
A31: 陸 | B31: 機電盤體工程 | I31: =工程預算書!G84 -> 10216.513 | K31: =I31*$K$5 -> 12566.311
A32: 1 | B32: 高壓盤體 | C32: =C21 -> kWp | D32: =$I$3 -> 70.55 | E32: 14000 | F32: =ROUND(E32*D32,0) -> 987700
A33: 2 | B33: 低壓盤體 | G33: 含AC、KWH、監控箱 | K33: =I33*$K$5 -> 0
A34: 3 | B34: 吊運費 | K34: =I34*$K$5 -> 0
A35: 柒 | B35: 機電配管線工程 | I35: =工程預算書!G95 -> 6612.6152 | K35: =I35*$K$5 -> 8133.5167
A36: 1 | B36: 電線電纜 | C36: =C32 -> kWp | D36: =$I$3 -> 70.55 | E36: 9100 | F36: =ROUND(E36*D36,0) -> 642005 | K36: =I36*$K$5 -> 0
A37: 2 | B37: 管材+鋁線槽 | K37: =I37*$K$5 -> 0
A38: 3 | B38: 大小五金另料 | G38: 角鐵、金屬軟管、接地線等 | K38: =I38*$K$5 -> 0
A39: 4 | B39: 機電安裝工資 | K39: =I39*$K$5 -> 0
A40: 捌 | B40: 簽證及各類文件申請跑件 | I40: =工程預算書!G105 -> 2435.7193 | K40: =I40*$K$5 -> 2995.9348
A41: 1 | B41: 機電技師簽證費 | C41: =C36 -> kWp | D41: =$I$3 -> 70.55 | E41: 3300 | F41: =ROUND(E41*D41,0) -> 232815 | K41: =I41*$K$5 -> 0
...

Sheet 工程預算書
A1: 工 程 預 算 書
A2: 業主： | B2: =報價單!B3 -> 夸克能源股份有限公司
A3: 工程地點： | B3: =報價單!B4 -> 宜蘭縣冬山鄉順安路185巷1號 | F3: REV： | G3: V1.0
A4: 工程名稱： | B4: =報價單!B5 -> 宜蘭順安美麗莊園-光電工程-70.55kWp | F4: 製表日期： | G4: =報價單!F3 -> 46153
A5: 設置容量： | B5: =報價單!I3 -> 70.55 | F5: 製表人：
A7: 壹 | B7: 鋼構工程
A8: 項次 | B8: 內 容 及 說 明 | C8: 單位 | D8: 數 量 | E8: 單 價 | F8: 總 價 | G8: 備 註
A9: 1 | B9: RH型鋼材料費用 | C9: kg | D9: 5016 | E9: 28 | F9: =E9*D9 -> 140448
A10: 2 | B10: 接合及連接板 | C10: kg | D10: =D9*0.15 -> 752.4 | E10: 40.5 | F10: =E10*D10 -> 30472.2
A11: 3 | B11: RH型鋼加工費(含一次加工,料損) | C11: kg | D11: =D9 -> 5016 | E11: 3 | F11: =E11*D11 -> 15048
A12: 4 | B12: RH型鋼二次加工費 | C12: kg | D12: =D10+D11 -> 5768.4 | E12: 10 | F12: =E12*D12 -> 57684
A13: 5 | B13: RH型鋼鍍鋅費用 | C13: kg | D13: =D12 -> 5768.4 | E13: 13 | F13: =E13*D13 -> 74989.2
A14: 6 | B14: 高張力螺絲(M16*60L) | C14: 組 | D14: 192 | E14: 53 | F14: =E14*D14 -> 10176
A15: 7 | B15: C型鋼材料費(A36/2.3T) | C15: kg | D15: =2673+185 -> 2858 | E15: 25 | F15: =E15*D15 -> 71450
A16: 8 | B16: C型鋼鍍鋅費用 | C16: =C15 -> kg | D16: =D15 -> 2858 | E16: 18 | F16: =E16*D16 -> 51444
A17: 9 | B17: C型鋼魚尾螺絲(M12*25L) | C17: 組 | D17: =392+48 -> 440 | E17: 9.5 | F17: =E17*D17 -> 4180
A18: 10 | B18: 鋼構運輸費用 | C18: kg | D18: =D13+D15 -> 8626.4 | E18: 4 | F18: =E18*D18 -> 34505.6
A19: 11 | B19: 鋼柱無收縮水泥 | C19: 座 | D19: 32 | E19: 300 | F19: =E19*D19 -> 9600
A20: 12 | B20: 基礎螺絲 | C20: 座 | D20: 32 | E20: 700 | F20: =E20*D20 -> 22400
A21: 13 | B21: 植筋膠 | C21: 支 | D21: =D20*6/15*1.05 -> 13.44 | E21: 550 | F21: =E21*D21 -> 7392
A22: 14 | B22: 爬梯 | C22: 座 | D22: 1 | E22: 38000 | F22: =E22*D22 -> 38000 | G22: 米數：4米
A23: 15 | B23: 爬梯安裝吊車 | C23: 式 | D23: 1 | E23: 15000 | F23: =E23*D23 -> 15000
A24: 16 | B24: 鋼構組立 | C24: kWp | D24: =B5 -> 70.55 | E24: 1800 | F24: =E24*D24 -> 126990
A25: 17 | B25: 五金另料 | C25: kWp | D25: =B5 -> 70.55 | E25: 50 | F25: =E25*D25 -> 3527.5
A26: 18 | B26: 機具費 | C26: kWp | D26: =B5 -> 70.55 | E26: 200 | F26: =E26*D26 -> 14110 | G26: 樓高：3樓
B28: 小計 | F28: =SUM(F9:F26) -> 727416.5 | G28: =F28/$B$5 -> 10310.652
A29: 貳 | B29: 浪板工程 | F29: =F36 -> 258745
A30: 項次 | B30: 內 容 及 說 明 | C30: 單位 | D30: 數 量 | E30: 單 價 | F30: 總 價 | G30: 備 註
A31: 1 | B31: 清浪板(0.5mm) | C31: 坪 | D31: =113.6+8.3 -> 121.9 | E31: 1650 | F31: =E31*D31 -> 201135 | G31: 含工帶料
A32: 2 | B32: 中脊與包邊 | C32: 呎 | D32: 150 | E32: 190 | F32: =D32*E32 -> 28500
A33: 3 | B33: 白鐵水槽+PVC排水管 | C33: kWp | D33: =B5 -> 70.55 | E33: 200 | F33: =E33*D33 -> 14110
A34: 4 | B34: 浪板吊運費 | C34: 式 | D34: 1 | E34: 15000 | F34: =E34*D34 -> 15000
B36: 小計 | F36: =SUM(F31:F34) -> 258745 | G36: =F36/$B$5 -> 3667.5408
A37: 參 | B37: 鋁擠支架及模組鋪設工程
A38: 項次 | B38: 內 容 及 說 明 | C38: 單位 | D38: 數 量 | E38: 單 價 | F38: 總 價 | G38: 備 註
A39: 1 | B39: 鋁支架材料費(含中壓.側壓.小五金) | C39: kWp | D39: =B5 -> 70.55 | E39: 3000 | F39: =E39*D39 -> 211650
A40: 2 | B40: 鋁支架吊運費 | C40: 式 | D40: 1 | E40: 15000 | F40: =E40*D40 -> 15000
A41: 3 | B41: 支架安裝+模組鋪設 | C41: kWp | D41: =B5 -> 70.55 | E41: 2000 | F41: =E41*D41 -> 141100
A42: 4 | B42: 安全母索立柱(角鐵)+繩 | C42: M | D42: 0 | E42: 800 | F42: =E42*D42 -> 0
A43: 5 | B43: 維修步道(角鐵鋼材料+菱形擴張網+母索) | C43: M | D43: 61 | E43: 950 | F43: =E43*D43 -> 57950
...
